Workbook

Sheet README
A1: Latin congress model
A2: What it does: estimates revenue, costs, result and break-even of a salsa and bachata congress in three sizes (300, 800 and 2,000 paying dancers). It is a planning tool, not a forecast.
A4: How to use it
A5: 1. Go to Inputs. Change only coloured cells. Choose the country in the first row: VAT, ticket fees, music rights and the local price level follow.
A6: 2. Orange cells are values nobody publishes (artist fees, hall rent, hotel price, sponsors): replace the placeholders with what organisers, venues and artists tell you.
A7: 3. Read the results on Results; Model shows every line; Sensitivity shows which lines move the result most.
A9: Colours
A10: Blue = public source (price list, tariff, fee page; see Sources).
A11: Green = market data from our sample of Latin events (see Market).
A12: Yellow = assumption, reasonable but not measured.
A13: Orange = to fill: no public value; the number shown is a placeholder.
A14: Grey = formula, do not type here.
... A25: Built by scripts/build_congress_model.py from research/economics/cost_benchmarks.csv and research/prices/latin_events_detail.csv (Dance Scene Atlas project, October 2026).

Sheet Results
A1: Measure | B1: How it is computed | C1: Small | D1: Medium | E1: Large
A2: Paying dancers | B2: input | C2: =Inputs!$C$39 -> 300 | D2: =Inputs!$D$39 -> 800 | E2: =Inputs!$E$39 -> 2000
A3: Total revenue | B3: Model | C3: =Model!C8 -> 24162.75 | D3: =Model!D8 -> 66434 | E3: =Model!E8 -> 169085
A4: Total costs | B4: Model | C4: =Model!C36 -> 35325.217 | D4: =Model!D36 -> 70774.397 | E4: =Model!E36 -> 140644.73
A5: Result | B5: revenue - costs | C5: =Model!C38 -> -11162.467 | D5: =Model!D38 -> -4340.3967 | E5: =Model!E38 -> 28440.274
A6: Margin | B6: result / revenue | C6: =IF(Model!C8=0,0,Model!C38/Model!C8) -> -0.46197004 | D6: =IF(Model!D8=0,0,Model!D38/Model!D8) -> -0.065333965 | E6: =IF(Model!E8=0,0,Model!E38/Model!E8) -> 0.16820105
A7: Cost per paying dancer | B7: costs / dancers | C7: =Model!C36/Inputs!$C$39 -> 117.75072 | D7: =Model!D36/Inputs!$D$39 -> 88.467996 | E7: =Model!E36/Inputs!$E$39 -> 70.322363
A8: Net revenue per dancer (tickets and hotel) | B8: (net ticket sales + hotel commission) / dancers | C8: =(Model!C4+Model!C5)/Inputs!$C$39 -> 80.5425 | D8: =(Model!D4+Model!D5)/Inputs!$D$39 -> 80.5425 | E8: =(Model!E4+Model!E5)/Inputs!$E$39 -> 80.5425
A9: Variable cost per dancer | B9: fees, wristband, marketing and its contingency per dancer | C9: =(Model!C33+Model!C34)/Inputs!$C$39+Inputs!$C$31*(1+Inputs!$C$36)+Inputs!$C$35*(Model!C4+Model!C5)/Inputs!$C$39 -> 11.598375 | D9: =(Model!D33+Model!D34)/Inputs!$D$39+Inputs!$C$31*(1+Inputs!$C$36)+Inputs!$C$35*(Model!D4+Model!D5)/Inputs!$D$39 -> 11.598375 | E9: =(Model!E33+Model!E34)/Inputs!$E$39+Inputs!$C$31*(1+Inputs!$C$36)+Inputs!$C$35*(Model!E4+Model!E5)/Inputs!$E$39 -> 11.598375
A10: Fixed costs of this set-up | B10: all other costs, net of sponsors and bar | C10: =Model!C36-Inputs!$C$39*C9-Model!C6-Model!C7 -> 31845.704 | D10: =Model!D36-Inputs!$D$39*D9-Model!D6-Model!D7 -> 59495.697 | E10: =Model!E36-Inputs!$E$39*E9-Model!E6-Model!E7 -> 109447.98
A11: Break-even dancers | B11: fixed costs / (net revenue - variable cost) per dancer | C11: =IF(C8-C9<=0,"never",C10/(C8-C9)) -> 461.90599 | D11: =IF(D8-D9<=0,"never",D10/(D8-D9)) -> 862.95528 | E11: =IF(E8-E9<=0,"never",E10/(E8-E9)) -> 1587.4881
A12: Result change per EUR of full pass price | B12: full-pass dancers x (1 - discount) x (net share - fees) | C12: =Inputs!$C$39*Inputs!$C$40*(1-Inputs!$C$9)*((1-Inputs!$C$35)/(1+Inputs!$C$60)-Inputs!$C$61-Inputs!$C$33) -> 146.1375 | D12: =Inputs!$D$39*Inputs!$D$40*(1-Inputs!$C$9)*((1-Inputs!$C$35)/(1+Inputs!$C$60)-Inputs!$C$61-Inputs!$C$33) -> 389.7 | E12: =Inputs!$E$39*Inputs!$E$40*(1-Inputs!$C$9)*((1-Inputs!$C$35)/(1+Inputs!$C$60)-Inputs!$C$61-Inputs!$C$33) -> 974.25
A13: Break-even full pass price (listed) | B13: price - result / change per EUR | C13: =Inputs!$C$8-C5/C12 -> 186.38331 | D13: =Inputs!$C$8-D5/D12 -> 121.13779 | E13: =Inputs!$C$8-E5/E12 -> 80.808033
A15: Read with care: orange inputs on Inputs are placeholders. Replace them with real offers before using the result.
A16: Biggest cost lines (medium scenario)
A17: =Model!A10 -> Artist fees | D17: =Model!D10 -> 9600 | E17: =IF(Model!D36=0,0,Model!D10/Model!D36) -> 0.13564227
A18: =Model!A11 -> Artist flights | D18: =Model!D11 -> 2276.0525 | E18: =IF(Model!D36=0,0,Model!D11/Model!D36) -> 0.032159264
A19: =Model!A12 -> Artist hotel | D19: =Model!D12 -> 3326.3603 | E19: =IF(Model!D36=0,0,Model!D12/Model!D36) -> 0.046999486
A20: =Model!A13 -> Artist meals | D20: =Model!D13 -> 1995.8162 | E20: =IF(Model!D36=0,0,Model!D13/Model!D36) -> 0.028199692
A21: =Model!A14 -> DJs | D21: =Model!D14 -> 3600 | E21: =IF(Model!D36=0,0,Model!D14/Model!D36) -> 0.050865852
A22: =Model!A16 -> Party hall | D22: =Model!D16 -> 7699.9081 | E22: =IF(Model!D36=0,0,Model!D16/Model!D36) -> 0.10879511
A23: =Model!A17 -> Workshop rooms | D23: =Model!D17 -> 2771.9669 | E23: =IF(Model!D36=0,0,Model!D17/Model!D36) -> 0.039166239
A24: =Model!A18 -> Dance floor | D24: =Model!D18 -> 3079.9632 | E24: =IF(Model!D36=0,0,Model!D18/Model!D36) -> 0.043518043
A25: =Model!A19 -> Sound and light | D25: =Model!D19 -> 6914.5175 | E25: =IF(Model!D36=0,0,Model!D19/Model!D36) -> 0.097698006
A26: =Model!A20 -> Music rights | D26: =Model!D20 -> 244.485 | E26: =IF(Model!D36=0,0,Model!D20/Model!D36) -> 0.0034544272
A27: =Model!A21 -> Decoration and stage | D27: =Model!D21 -> 821.32353 | E27: =IF(Model!D36=0,0,Model!D21/Model!D36) -> 0.011604811
A28: =Model!A23 -> Security | D28: =Model!D23 -> 3029.575 | E28: =IF(Model!D36=0,0,Model!D23/Model!D36) -> 0.042806088
A29: =Model!A24 -> First aid | D29: =Model!D24 -> 1724.7794 | E29: =IF(Model!D36=0,0,Model!D24/Model!D36) -> 0.024370104
A30: =Model!A25 -> Photo and video | D30: =Model!D25 -> 5543.9338 | E30: =IF(Model!D36=0,0,Model!D25/Model!D36) -> 0.078332477
A31: =Model!A26 -> Volunteers' meals | D31: =Model!D26 -> 985.58824 | E31: =IF(Model!D36=0,0,Model!D26/Model!D36) -> 0.013925774
A32: =Model!A27 -> Wristbands and passes | D32: =Model!D27 -> 80 | E32: =IF(Model!D36=0,0,Model!D27/Model!D36) -> 0.0011303523
A33: =Model!A28 -> Insurance | D33: =Model!D28 -> 400 | E33: =IF(Model!D36=0,0,Model!D28/Model!D36) -> 0.0056517614
A34: =Model!A29 -> Website, software, admin | D34: =Model!D29 -> 1000 | E34: =IF(Model!D36=0,0,Model!D29/Model!D36) -> 0.014129403
A35: =Model!A30 -> Accounting and legal | D35: =Model!D30 -> 800 | E35: =IF(Model!D36=0,0,Model!D30/Model!D36) -> 0.011303523
A36: =Model!A32 -> Contingency | D36: =Model!D32 -> 5589.427 | E36: =IF(Model!D36=0,0,Model!D32/Model!D36) -> 0.078975268
A37: =Model!A33 -> Ticket platform fees | D37: =Model!D33 -> 4702.5 | E37: =IF(Model!D36=0,0,Model!D33/Model!D36) -> 0.066443519
A38: =Model!A34 -> Card payment fees | D38: =Model!D34 -> 1266.5 | E38: =IF(Model!D36=0,0,Model!D34/Model!D36) -> 0.017894889
A39: =Model!A35 -> Marketing | D39: =Model!D35 -> 3321.7 | E39: =IF(Model!D36=0,0,Model!D35/Model!D36) -> 0.046933639
D40: EUR | E40: share of costs

Sheet Inputs
A1: Input | B1: Unit | C1: Small | D1: Medium | E1: Large | F1: Basis | G1: Note
A2: General inputs (one value for all scenarios: column Small)
A3: Country of the event | B3: code | C3: AT | F3: assumption | G3: Choose from the list; drives VAT, ticket fees, music rights and the local price level
A4: Use the reduced VAT rate? | B4: yes/no | C4: no | F4: assumption | G4: Dance parties are often taxed at the standard rate; workshops and cultural shows may get a reduced rate. Check with a tax adviser
A5: Scale local costs to the country's price level? | B5: yes/no | C5: yes | F5: assumption | G5: Most cost benchmarks are German prices; 'yes' multiplies local costs by price level of the country / Germany
A6: Event days | B6: days | C6: 3 | F6: market data | G6: Median length of 149 Latin events (rounds AA1, AB)
A7: Party nights | B7: nights | C7: 3 | F7: market data | G7: Typical: Friday to Sunday
A8: Full pass, listed price | B8: EUR incl. VAT | C8: 110 | F8: market data | G8: Median of 85 randomly drawn Latin events (AA1, AB). Country medians on the sheet Market
A9: Average discount vs listed price | B9: % | C9: 0.1 | F9: assumption | G9: Early birds, group and promo codes
A10: Party-only pass | B10: EUR incl. VAT | C10: 65 | F10: market data | G10: Median of 14 events that publish a party pass
A11: Dancers booking the organiser's hotel package | B11: % | C11: 0.3 | F11: assumption | G11: To check with organisers
A12: Hotel package price per person per night | B12: EUR | C12: 60 | F12: to fill | G12: Room price agreed with the hotel
A13: Hotel commission paid to the organiser | B13: % | C13: 0.12 | F13: source | G13: Kempinski group terms: 12% on net room revenue (AA3, K14)
A14: Fee per teaching artist (couple or solo), weekend | B14: EUR | C14: 800 | F14: to fill | G14: Not public. Placeholder only: ask organisers and artists
A15: People per teaching artist (couples count 2) | B15: people | C15: 1.8 | F15: assumption | G15: Most line-ups are couples
A16: Share of artists who fly in | B16: % | C16: 0.8 | F16: assumption | G16: 27 of the 51 most booked artists with a stated base live in Spain (AB)
A17: Average one-way fare | B17: EUR | C17: 50.66 | F17: source | G17: Ryanair average fare FY26, without extras (AA3, K10)
A18: Extras on flights (bags, dates) | B18: % | C18: 0.3 | F18: assumption
A19: Hotel room per artist per night | B19: EUR | C19: 90 | F19: assumption | G19: One room per couple or solo
A20: Meals per artist person per day | B20: EUR | C20: 30 | F20: assumption
A21: DJ fee per night | B21: EUR | C21: 250 | F21: to fill | G21: Not public
A22: Travel per DJ | B22: EUR | C22: 150 | F22: assumption
A23: Workshop room, rent per day | B23: EUR | C23: 300 | F23: assumption | G23: Public venue prices found only for small halls (Graz EUR 400-937 per day, about 240 people)
A24: Rent a dance floor for the party hall? | B24: yes/no | C24: yes | F24: assumption | G24: 'no' if the venue has a suitable floor
A25: Dance floor, price per m2 for the event | B25: EUR | C25: 15 | F25: source | G25: Parquet floor 36 m2 for EUR 540 per day (AA3, K6); assumed charged once for a weekend hire
A26: Sound, workshop room, per day | B26: EUR | C26: 420 | F26: source | G26: Package up to 100 people (AA3, K7)
A27: Security staff, per hour | B27: EUR | C27: 46.84 | F27: source | G27: German security collective agreement (AA3, K9)
A28: Hours of security and first aid per night | B28: hours | C28: 7 | F28: assumption
A29: First aid staff, per hour | B29: EUR | C29: 40 | F29: assumption | G29: No public tariff found
A30: Photographer or videographer, per day | B30: EUR | C30: 900 | F30: source | G30: Full day in ES and DE (AA3, K13)
A31: Wristband or printed pass, per dancer | B31: EUR | C31: 0.1 | F31: source | G31: Printed vinyl wristbands, EUR 100 per 1,000 (AA3, K12)
A32: Meals per volunteer per day | B32: EUR | C32: 20 | F32: assumption | G32: Volunteers get a free pass and meals
A33: Card payment fee | B33: % | C33: 0.015 | F33: source | G33: Stripe, EEA cards (AA3, K3)
A34: Card payment fee, fixed per ticket | B34: EUR | C34: 0.25 | F34: source | G34: Stripe, EEA cards (AA3, K3)
A35: Marketing (ads, design, promotion) | B35: % of revenue | C35: 0.05 | F35: assumption
A36: Contingency on production costs | B36: % | C36: 0.1 | F36: assumption
A38: Scenario inputs
A39: Paying dancers | B39: dancers | C39: 300 | D39: 800 | E39: 2000 | F39: assumption | G39: Three sizes; the 10 largest European congresses average about 2,400 (round Z)
A40: Share of dancers on a full pass | B40: % | C40: 0.75 | D40: 0.75 | E40: 0.75 | F40: assumption | G40: The rest buy party-only passes
A41: Teaching artists (couples or solo) | B41: artists | C41: 6 | D41: 12 | E41: 25 | F41: market data | G41: Line-ups have a median of 9 teaching artists (61 events, AA1, AB)
...

Sheet Sensitivity
A1: Line or input (medium scenario) | B1: Value | C1: Result if 20% lower | D1: Result if 20% higher | E1: Swing
A2: Full pass price | B2: =Inputs!$C$8 -> 110 | C2: =Results!D5-0.2*Inputs!$C$8*Results!D12 -> -12913.797 | D2: =Results!D5+0.2*Inputs!$C$8*Results!D12 -> 4233.0033 | E2: =D2-C2 -> 17146.8
A3: Paying dancers (same set-up) | B3: =Inputs!$D$39 -> 800 | C3: =Results!D5-0.2*Inputs!$D$39*(Results!D8-Results!D9) -> -15371.457 | D3: =Results!D5+0.2*Inputs!$D$39*(Results!D8-Results!D9) -> 6690.6633 | E3: =D3-C3 -> 22062.12
A4: =Model!A10 -> Artist fees | B4: =Model!D10 -> 9600 | C4: =Results!D5+0.2*Model!D10 -> -2420.3967 | D4: =Results!D5-0.2*Model!D10 -> -6260.3967 | E4: =C4-D4 -> 3840
A5: =Model!A16 -> Party hall | B5: =Model!D16 -> 7699.9081 | C5: =Results!D5+0.2*Model!D16 -> -2800.415 | D5: =Results!D5-0.2*Model!D16 -> -5880.3783 | E5: =C5-D5 -> 3079.9632
A6: =Model!A19 -> Sound and light | B6: =Model!D19 -> 6914.5175 | C6: =Results!D5+0.2*Model!D19 -> -2957.4932 | D6: =Results!D5-0.2*Model!D19 -> -5723.3001 | E6: =C6-D6 -> 2765.807
A7: =Model!A32 -> Contingency | B7: =Model!D32 -> 5589.427 | C7: =Results!D5+0.2*Model!D32 -> -3222.5113 | D7: =Results!D5-0.2*Model!D32 -> -5458.282 | E7: =C7-D7 -> 2235.7708
A8: =Model!A25 -> Photo and video | B8: =Model!D25 -> 5543.9338 | C8: =Results!D5+0.2*Model!D25 -> -3231.6099 | D8: =Results!D5-0.2*Model!D25 -> -5449.1834 | E8: =C8-D8 -> 2217.5735
A9: =Model!A33 -> Ticket platform fees | B9: =Model!D33 -> 4702.5 | C9: =Results!D5+0.2*Model!D33 -> -3399.8967 | D9: =Results!D5-0.2*Model!D33 -> -5280.8967 | E9: =C9-D9 -> 1881
A10: =Model!A14 -> DJs | B10: =Model!D14 -> 3600 | C10: =Results!D5+0.2*Model!D14 -> -3620.3967 | D10: =Results!D5-0.2*Model!D14 -> -5060.3967 | E10: =C10-D10 -> 1440
A11: =Model!A12 -> Artist hotel | B11: =Model!D12 -> 3326.3603 | C11: =Results!D5+0.2*Model!D12 -> -3675.1246 | D11: =Results!D5-0.2*Model!D12 -> -5005.6687 | E11: =C11-D11 -> 1330.5441
A12: =Model!A35 -> Marketing | B12: =Model!D35 -> 3321.7 | C12: =Results!D5+0.2*Model!D35 -> -3676.0567 | D12: =Results!D5-0.2*Model!D35 -> -5004.7367 | E12: =C12-D12 -> 1328.68
A13: =Model!A18 -> Dance floor | B13: =Model!D18 -> 3079.9632 | C13: =Results!D5+0.2*Model!D18 -> -3724.404 | D13: =Results!D5-0.2*Model!D18 -> -4956.3893 | E13: =C13-D13 -> 1231.9853
A14: =Model!A23 -> Security | B14: =Model!D23 -> 3029.575 | C14: =Results!D5+0.2*Model!D23 -> -3734.4816 | D14: =Results!D5-0.2*Model!D23 -> -4946.3117 | E14: =C14-D14 -> 1211.83
A15: =Model!A17 -> Workshop rooms | B15: =Model!D17 -> 2771.9669 | C15: =Results!D5+0.2*Model!D17 -> -3786.0033 | D15: =Results!D5-0.2*Model!D17 -> -4894.79 | E15: =C15-D15 -> 1108.7868
A16: =Model!A11 -> Artist flights | B16: =Model!D11 -> 2276.0525 | C16: =Results!D5+0.2*Model!D11 -> -3885.1862 | D16: =Results!D5-0.2*Model!D11 -> -4795.6072 | E16: =C16-D16 -> 910.42099
A17: =Model!A13 -> Artist meals | B17: =Model!D13 -> 1995.8162 | C17: =Results!D5+0.2*Model!D13 -> -3941.2334 | D17: =Results!D5-0.2*Model!D13 -> -4739.5599 | E17: =C17-D17 -> 798.32647
A18: =Model!A24 -> First aid | B18: =Model!D24 -> 1724.7794 | C18: =Results!D5+0.2*Model!D24 -> -3995.4408 | D18: =Results!D5-0.2*Model!D24 -> -4685.3525 | E18: =C18-D18 -> 689.91176
A19: =Model!A34 -> Card payment fees | B19: =Model!D34 -> 1266.5 | C19: =Results!D5+0.2*Model!D34 -> -4087.0967 | D19: =Results!D5-0.2*Model!D34 -> -4593.6967 | E19: =C19-D19 -> 506.6
A20: =Model!A29 -> Website, software, admin | B20: =Model!D29 -> 1000 | C20: =Results!D5+0.2*Model!D29 -> -4140.3967 | D20: =Results!D5-0.2*Model!D29 -> -4540.3967 | E20: =C20-D20 -> 400
A21: =Model!A26 -> Volunteers' meals | B21: =Model!D26 -> 985.58824 | C21: =Results!D5+0.2*Model!D26 -> -4143.279 | D21: =Results!D5-0.2*Model!D26 -> -4537.5143 | E21: =C21-D21 -> 394.23529
A22: =Model!A21 -> Decoration and stage | B22: =Model!D21 -> 821.32353 | C22: =Results!D5+0.2*Model!D21 -> -4176.1319 | D22: =Results!D5-0.2*Model!D21 -> -4504.6614 | E22: =C22-D22 -> 328.52941
A23: =Model!A30 -> Accounting and legal | B23: =Model!D30 -> 800 | C23: =Results!D5+0.2*Model!D30 -> -4180.3967 | D23: =Results!D5-0.2*Model!D30 -> -4500.3967 | E23: =C23-D23 -> 320
A24: =Model!A28 -> Insurance | B24: =Model!D28 -> 400 | C24: =Results!D5+0.2*Model!D28 -> -4260.3967 | D24: =Results!D5-0.2*Model!D28 -> -4420.3967 | E24: =C24-D24 -> 160
A25: =Model!A20 -> Music rights | B25: =Model!D20 -> 244.485 | C25: =Results!D5+0.2*Model!D20 -> -4291.4997 | D25: =Results!D5-0.2*Model!D20 -> -4389.2937 | E25: =C25-D25 -> 97.794
A26: =Model!A27 -> Wristbands and passes | B26: =Model!D27 -> 80 | C26: =Results!D5+0.2*Model!D27 -> -4324.3967 | D26: =Results!D5-0.2*Model!D27 -> -4356.3967 | E26: =C26-D26 -> 32
A28: Cost lines: 20% lower cost = higher result. Lines are ordered by size with the default inputs; the swing updates with your inputs.

Sheet Model
A1: Line | B1: How it is computed | C1: Small | D1: Medium | E1: Large
A2: Revenue
A3: Ticket sales, gross (incl. VAT) | B3: dancers x (full share x full pass + rest x party pass) x (1 - discount) | C3: =Inputs!$C$39*(Inputs!$C$40*Inputs!$C$8+(1-Inputs!$C$40)*Inputs!$C$10)*(1-Inputs!$C$9) -> 26662.5 | D3: =Inputs!$D$39*(Inputs!$D$40*Inputs!$C$8+(1-Inputs!$D$40)*Inputs!$C$10)*(1-Inputs!$C$9) -> 71100 | E3: =Inputs!$E$39*(Inputs!$E$40*Inputs!$C$8+(1-Inputs!$E$40)*Inputs!$C$10)*(1-Inputs!$C$9) -> 177750
A4: Ticket sales, net of VAT | B4: gross / (1 + VAT) | C4: =C3/(1+Inputs!$C$60) -> 22218.75 | D4: =D3/(1+Inputs!$C$60) -> 59250 | E4: =E3/(1+Inputs!$C$60) -> 148125
A5: Hotel commission | B5: dancers x hotel share x price per night x nights x commission | C5: =Inputs!$C$39*Inputs!$C$11*Inputs!$C$12*Inputs!$C$7*Inputs!$C$13 -> 1944 | D5: =Inputs!$D$39*Inputs!$C$11*Inputs!$C$12*Inputs!$C$7*Inputs!$C$13 -> 5184 | E5: =Inputs!$E$39*Inputs!$C$11*Inputs!$C$12*Inputs!$C$7*Inputs!$C$13 -> 12960
A6: Sponsors and stands | B6: input | C6: =Inputs!$C$56 -> 0 | D6: =Inputs!$D$56 -> 2000 | E6: =Inputs!$E$56 -> 8000
A7: Share of bar sales | B7: input | C7: =Inputs!$C$57 -> 0 | D7: =Inputs!$D$57 -> 0 | E7: =Inputs!$E$57 -> 0
A8: Total revenue | B8: sum | C8: =SUM(C4:C7) -> 24162.75 | D8: =SUM(D4:D7) -> 66434 | E8: =SUM(E4:E7) -> 169085
A9: Artists and programme
A10: Artist fees | B10: teaching artists x fee | C10: =Inputs!$C$41*Inputs!$C$14 -> 4800 | D10: =Inputs!$D$41*Inputs!$C$14 -> 9600 | E10: =Inputs!$E$41*Inputs!$C$14 -> 20000
A11: Artist flights | B11: artists x people x share flying x fare x 2 x (1 + extras) | C11: =Inputs!$C$41*Inputs!$C$15*Inputs!$C$16*Inputs!$C$17*2*(1+Inputs!$C$18) -> 1138.0262 | D11: =Inputs!$D$41*Inputs!$C$15*Inputs!$C$16*Inputs!$C$17*2*(1+Inputs!$C$18) -> 2276.0525 | E11: =Inputs!$E$41*Inputs!$C$15*Inputs!$C$16*Inputs!$C$17*2*(1+Inputs!$C$18) -> 4741.776
A12: Artist hotel | B12: artists x room per night x days x price factor | C12: =Inputs!$C$41*Inputs!$C$19*Inputs!$C$6*Inputs!$C$64 -> 1663.1801 | D12: =Inputs!$D$41*Inputs!$C$19*Inputs!$C$6*Inputs!$C$64 -> 3326.3603 | E12: =Inputs!$E$41*Inputs!$C$19*Inputs!$C$6*Inputs!$C$64 -> 6929.9173
A13: Artist meals | B13: artists x people x meals per day x days x price factor | C13: =Inputs!$C$41*Inputs!$C$15*Inputs!$C$20*Inputs!$C$6*Inputs!$C$64 -> 997.90809 | D13: =Inputs!$D$41*Inputs!$C$15*Inputs!$C$20*Inputs!$C$6*Inputs!$C$64 -> 1995.8162 | E13: =Inputs!$E$41*Inputs!$C$15*Inputs!$C$20*Inputs!$C$6*Inputs!$C$64 -> 4157.9504
A14: DJs | B14: DJs x (fee x nights + travel) | C14: =Inputs!$C$42*(Inputs!$C$21*Inputs!$C$7+Inputs!$C$22) -> 1800 | D14: =Inputs!$D$42*(Inputs!$C$21*Inputs!$C$7+Inputs!$C$22) -> 3600 | E14: =Inputs!$E$42*(Inputs!$C$21*Inputs!$C$7+Inputs!$C$22) -> 5400
A15: Venue and production
A16: Party hall | B16: rent per day x days x price factor | C16: =Inputs!$C$44*Inputs!$C$6*Inputs!$C$64 -> 3079.9632 | D16: =Inputs!$D$44*Inputs!$C$6*Inputs!$C$64 -> 7699.9081 | E16: =Inputs!$E$44*Inputs!$C$6*Inputs!$C$64 -> 18479.779
A17: Workshop rooms | B17: rooms x rent per day x days x price factor | C17: =Inputs!$C$43*Inputs!$C$23*Inputs!$C$6*Inputs!$C$64 -> 1847.9779 | D17: =Inputs!$D$43*Inputs!$C$23*Inputs!$C$6*Inputs!$C$64 -> 2771.9669 | E17: =Inputs!$E$43*Inputs!$C$23*Inputs!$C$6*Inputs!$C$64 -> 4619.9449
A18: Dance floor | B18: if needed: m2 x price per m2 x price factor | C18: =IF(Inputs!$C$24="yes",Inputs!$C$45*Inputs!$C$25*Inputs!$C$64,0) -> 1539.9816 | D18: =IF(Inputs!$C$24="yes",Inputs!$D$45*Inputs!$C$25*Inputs!$C$64,0) -> 3079.9632 | E18: =IF(Inputs!$C$24="yes",Inputs!$E$45*Inputs!$C$25*Inputs!$C$64,0) -> 6159.9265
A19: Sound and light | B19: (party hall + rooms x room package) x days x price factor | C19: =(Inputs!$C$46+Inputs!$C$43*Inputs!$C$26)*Inputs!$C$6*Inputs!$C$64 -> 4265.7491 | D19: =(Inputs!$D$46+Inputs!$D$43*Inputs!$C$26)*Inputs!$C$6*Inputs!$C$64 -> 6914.5175 | E19: =(Inputs!$E$46+Inputs!$E$43*Inputs!$C$26)*Inputs!$C$6*Inputs!$C$64 -> 12535.45
A20: Music rights | B20: fee per night x size factor x nights | C20: =Inputs!$C$63*Inputs!$C$47*Inputs!$C$7 -> 162.99 | D20: =Inputs!$C$63*Inputs!$D$47*Inputs!$C$7 -> 244.485 | E20: =Inputs!$C$63*Inputs!$E$47*Inputs!$C$7 -> 488.97
A21: Decoration and stage | B21: input x price factor | C21: =Inputs!$C$53*Inputs!$C$64 -> 307.99632 | D21: =Inputs!$D$53*Inputs!$C$64 -> 821.32353 | E21: =Inputs!$E$53*Inputs!$C$64 -> 2053.3088
A22: Staff and services
A23: Security | B23: staff x hours x rate x nights x price factor | C23: =Inputs!$C$48*Inputs!$C$28*Inputs!$C$27*Inputs!$C$7*Inputs!$C$64 -> 2019.7167 | D23: =Inputs!$D$48*Inputs!$C$28*Inputs!$C$27*Inputs!$C$7*Inputs!$C$64 -> 3029.575 | E23: =Inputs!$E$48*Inputs!$C$28*Inputs!$C$27*Inputs!$C$7*Inputs!$C$64 -> 6059.1501
A24: First aid | B24: staff x hours x rate x nights x price factor | C24: =Inputs!$C$49*Inputs!$C$28*Inputs!$C$29*Inputs!$C$7*Inputs!$C$64 -> 862.38971 | D24: =Inputs!$D$49*Inputs!$C$28*Inputs!$C$29*Inputs!$C$7*Inputs!$C$64 -> 1724.7794 | E24: =Inputs!$E$49*Inputs!$C$28*Inputs!$C$29*Inputs!$C$7*Inputs!$C$64 -> 2587.1691
A25: Photo and video | B25: people x day rate x days x price factor | C25: =Inputs!$C$51*Inputs!$C$30*Inputs!$C$6*Inputs!$C$64 -> 2771.9669 | D25: =Inputs!$D$51*Inputs!$C$30*Inputs!$C$6*Inputs!$C$64 -> 5543.9338 | E25: =Inputs!$E$51*Inputs!$C$30*Inputs!$C$6*Inputs!$C$64 -> 5543.9338
A26: Volunteers' meals | B26: volunteers x meals x days x price factor | C26: =Inputs!$C$50*Inputs!$C$32*Inputs!$C$6*Inputs!$C$64 -> 492.79412 | D26: =Inputs!$D$50*Inputs!$C$32*Inputs!$C$6*Inputs!$C$64 -> 985.58824 | E26: =Inputs!$E$50*Inputs!$C$32*Inputs!$C$6*Inputs!$C$64 -> 2155.9743
A27: Wristbands and passes | B27: dancers x price per piece | C27: =Inputs!$C$39*Inputs!$C$31 -> 30 | D27: =Inputs!$D$39*Inputs!$C$31 -> 80 | E27: =Inputs!$E$39*Inputs!$C$31 -> 200
A28: Insurance | B28: input | C28: =Inputs!$C$52 -> 200 | D28: =Inputs!$D$52 -> 400 | E28: =Inputs!$E$52 -> 994
A29: Website, software, admin | B29: input | C29: =Inputs!$C$54 -> 500 | D29: =Inputs!$D$54 -> 1000 | E29: =Inputs!$E$54 -> 2000
A30: Accounting and legal | B30: input | C30: =Inputs!$C$55 -> 500 | D30: =Inputs!$D$55 -> 800 | E30: =Inputs!$E$55 -> 1500
A31: Fees, marketing, contingency
A32: Contingency | B32: contingency % x production costs above | C32: =Inputs!$C$36*(SUM(C10:C30)) -> 2898.064 | D32: =Inputs!$C$36*(SUM(D10:D30)) -> 5589.427 | E32: =Inputs!$C$36*(SUM(E10:E30)) -> 10660.725
A33: Ticket platform fees | B33: gross sales x fee % + dancers x fixed fee | C33: =C3*Inputs!$C$61+Inputs!$C$39*Inputs!$C$62 -> 1763.4375 | D33: =D3*Inputs!$C$61+Inputs!$D$39*Inputs!$C$62 -> 4702.5 | E33: =E3*Inputs!$C$61+Inputs!$E$39*Inputs!$C$62 -> 11756.25
A34: Card payment fees | B34: gross sales x fee % + dancers x fixed fee | C34: =C3*Inputs!$C$33+Inputs!$C$39*Inputs!$C$34 -> 474.9375 | D34: =D3*Inputs!$C$33+Inputs!$D$39*Inputs!$C$34 -> 1266.5 | E34: =E3*Inputs!$C$33+Inputs!$E$39*Inputs!$C$34 -> 3166.25
A35: Marketing | B35: marketing % x total revenue | C35: =Inputs!$C$35*C8 -> 1208.1375 | D35: =Inputs!$C$35*D8 -> 3321.7 | E35: =Inputs!$C$35*E8 -> 8454.25
A36: Total costs | B36: sum of all cost lines | C36: =SUM(C10:C30)+C32+C33+C34+C35 -> 35325.217 | D36: =SUM(D10:D30)+D32+D33+D34+D35 -> 70774.397 | E36: =SUM(E10:E30)+E32+E33+E34+E35 -> 140644.73
A37: Result
A38: Result (revenue - costs) | C38: =C8-C36 -> -11162.467 | D38: =D8-D36 -> -4340.3967 | E38: =E8-E36 -> 28440.274

Sheet Country
A1: Code | B1: Country | C1: VAT standard | D1: VAT reduced (may apply, verify) | E1: Ticket platform fee % | F1: Ticket platform fee, fixed EUR | G1: Music rights per night EUR | H1: Price level (EU = 100) | I1: Market median full pass EUR | J1: Events with a price
A2: AT | B2: Austria | C2: 0.2 | D2: 0.13 | E2: 0.055 | F2: 0.99 | G2: 54.33 | H2: 111.7 | J2: 0
A3: DE | B3: Germany | C3: 0.19 | D3: 0.07 | E3: 0.055 | F3: 0.99 | G3: 152 | H3: 108.8 | I3: 115 | J3: 14
A4: ES | B4: Spain | C4: 0.21 | D4: 0.1 | E4: 0.09 | F4: 0.19 | H4: 91.3 | I4: 114.5 | J4: 26
A5: IT | B5: Italy | C5: 0.22 | D5: 0.1 | E5: 0.055 | F5: 0.99 | H5: 97 | I5: 115 | J5: 9
A6: FR | B6: France | C6: 0.2 | D6: 0.055 | E6: 0.055 | F6: 0.99 | H6: 111.2 | I6: 132.5 | J6: 6
A7: NL | B7: Netherlands | C7: 0.21 | D7: 0.09 | E7: 0.04 | F7: 0.99 | H7: 115.1 | J7: 3
A8: PL | B8: Poland | C8: 0.23 | D8: 0.08 | E8: 0.025 | F8: 1.37 | H8: 72.3 | I8: 130.4 | J8: 6
A9: CZ | B9: Czechia | C9: 0.21 | D9: 0.12 | E9: 0.025 | F9: 0.78 | H9: 88.5 | J9: 2
A10: GB | B10: United Kingdom | C10: 0.2 | D10: 0.2 | E10: 0.0695 | F10: 0.7 | H10: 125.1 | J10: 2
A12: VAT standard: PwC Worldwide Tax Summaries (AA3, K1). Reduced: rates that may apply to cultural events or performances; dance parties are often at the standard rate: verify.
A13: Ticket platform: Eventbrite Professional package, per country (AA3, K2). goandance does not publish its commission.
A14: Music rights: Germany GEMA tariff, about 500 m2, 500-1,500 people; Austria AKM minimum fee for 401-500 people (AA3, K4). Empty = not found: the model uses the German value.
A15: Price level: Eurostat tec00120, 2024. Market median: only countries with 5+ events with a price (AA1, AB).

Sheet Market
A1: Group | B1: Events | C1: Median full pass EUR | D1: Note
A2: All, random sample | B2: 85 | C2: 110 | D2: Latin congresses and festivals of the next 12 months drawn at random (seed 20261021)
A3: 1-2 days | B3: 6 | C3: 87.5 | D3: all events with a price
A4: 3 days | B4: 42 | C4: 105 | D4: all events with a price
A5: 4+ days | B5: 40 | C5: 115 | D5: all events with a price
A6: Country ES | B6: 26 | C6: 114.5
A7: Country DE | B7: 14 | C7: 115
A8: Country IT | B8: 9 | C8: 115
A9: Country PL | B9: 6 | C9: 130.4
A10: Country FR | B10: 6 | C10: 132.5
A11: Party-only pass | B11: 14 | C11: 65 | D11: events that publish one
A13: Source: research/prices/latin_events_detail.csv (rounds AA1 and AB, October 2026); prices as listed on the access day, tier mostly unknown.

Sheet Sources
A1: Item | B1: Country | C1: Value EUR | D1: Low | E1: High | F1: Unit | G1: VAT incl. | H1: Year | I1: Source | J1: Link | K1: Notes
A2: K1_vat_tickets | B2: AT | C2: 20 | F2: percent | G2: n/a | H2: 2026 | I2: PwC Worldwide Tax Summaries | J2: https://taxsummaries.pwc.com/quick-charts/value-added-tax-vat-rates | K2: standard VAT rate; no reduced rate specifically for dance tickets on the public page
A3: K1_vat_tickets | B3: DE | C3: 19 | F3: percent | G3: n/a | H3: 2026 | I3: PwC Worldwide Tax Summaries | J3: https://taxsummaries.pwc.com/quick-charts/value-added-tax-vat-rates | K3: standard VAT rate; no reduced rate specifically for dance tickets on the public page
A4: K1_vat_tickets | B4: ES | C4: 21 | F4: percent | G4: n/a | H4: 2026 | I4: PwC Worldwide Tax Summaries | J4: https://taxsummaries.pwc.com/quick-charts/value-added-tax-vat-rates | K4: standard VAT rate; no reduced rate specifically for dance tickets on the public page
A5: K1_vat_tickets | B5: IT | C5: 22 | F5: percent | G5: n/a | H5: 2026 | I5: PwC Worldwide Tax Summaries | J5: https://taxsummaries.pwc.com/quick-charts/value-added-tax-vat-rates | K5: standard VAT rate; no reduced rate specifically for dance tickets on the public page
A6: K1_vat_tickets | B6: FR | C6: 20 | F6: percent | G6: n/a | H6: 2026 | I6: PwC Worldwide Tax Summaries | J6: https://taxsummaries.pwc.com/quick-charts/value-added-tax-vat-rates | K6: standard VAT rate; no reduced rate specifically for dance tickets on the public page
A7: K1_vat_tickets | B7: NL | C7: 21 | F7: percent | G7: n/a | H7: 2026 | I7: PwC Worldwide Tax Summaries | J7: https://taxsummaries.pwc.com/quick-charts/value-added-tax-vat-rates | K7: standard VAT rate; no reduced rate specifically for dance tickets on the public page
A8: K1_vat_tickets | B8: PL | C8: 23 | F8: percent | G8: n/a | H8: 2026 | I8: PwC Worldwide Tax Summaries | J8: https://taxsummaries.pwc.com/quick-charts/value-added-tax-vat-rates | K8: standard VAT rate; no reduced rate specifically for dance tickets on the public page
A9: K1_vat_tickets | B9: CZ | C9: 21 | F9: percent | G9: n/a | H9: 2026 | I9: PwC Worldwide Tax Summaries | J9: https://taxsummaries.pwc.com/quick-charts/value-added-tax-vat-rates | K9: standard VAT rate; no reduced rate specifically for dance tickets on the public page
A10: K1_vat_tickets | B10: GB | C10: 20 | F10: percent | G10: n/a | H10: 2026 | I10: PwC Worldwide Tax Summaries | J10: https://taxsummaries.pwc.com/quick-charts/value-added-tax-vat-rates | K10: standard VAT rate; no reduced rate specifically for dance tickets on the public page
A11: K2_ticketing_fee | B11: AT | C11: 5.5 | F11: percent of ticket price | G11: yes | H11: 2026 | I11: Eventbrite pricing | J11: https://www.eventbrite.com/organizer/pricing/ | K11: Professional package; service fee; fixed part in a separate row
A12: K2_ticketing_fee | B12: AT | C12: 0.99 | F12: EUR per sold ticket | G12: yes | H12: 2026 | I12: Eventbrite pricing | J12: https://www.eventbrite.com/organizer/pricing/ | K12: fixed part per sold ticket
A13: K2_ticketing_fee | B13: DE | C13: 5.5 | F13: percent of ticket price | G13: yes | H13: 2026 | I13: Eventbrite pricing | J13: https://www.eventbrite.com/organizer/pricing/ | K13: Professional package; service fee; fixed part in a separate row
... A57: K7_sound_light | B57: DE | C57: 985 | F57: EUR per day | G57: no | H57: 2026 | I57: Sound for you | J57: https://www.sound-for-you.de/ | K57: package XXL up to 1,000 people
A58: K8_insurance | B58: GB | D58: 82.3 | E58: 993.6 | F58: EUR per event | G58: unknown | H58: 2026 | I58: events-insurance.co.uk | J58: https://www.events-insurance.co.uk/ | K58: public liability up to GBP 10m; GBP 69 (up to 100 visitors) to GBP 833; converted at ECB 0.83825 GBP/EUR
A59: K9_first_aid_security | B59: DE | C59: 46.84 | F59: EUR per hour | G59: unknown | H59: 2026 | I59: security collective agreement | J59: https://www.wko.at/ | K59: security staff hourly wage
A60: K10_flights | B60: IE | C60: 50.66 | F60: EUR per one-way ticket | G60: unknown | H60: 2026 | I60: Ryanair annual report FY26 | J60: https://investor.ryanair.com/ | K60: average booked passenger fare; European short-haul; not country-specific
A61: K11_artist_fees | B61: FR | D61: 55 | E61: 75 | F61: EUR per hour | G61: unknown | H61: 2026 | I61: private bachata teachers | J61: https://www.superprof.fr/ | K61: private lesson range
A62: K11_artist_fees | B62: ES | D62: 25 | E62: 50 | F62: EUR per hour (individual) | G62: unknown | H62: 2026 | I62: salsa/bachata teachers | J62: https://www.superprof.es/ | K62: individual lesson range
A63: K11_artist_fees | B63: ES | D63: 15 | E63: 30 | F63: EUR per person per hour (group) | G63: unknown | H63: 2026 | I63: salsa/bachata teachers | J63: https://www.superprof.es/ | K63: group lesson range
A64: K11_artist_fees | B64: NL | D64: 10.74 | E64: 16.17 | F64: EUR per person per hour (group) | G64: unknown | H64: 2026 | I64: dance schools | J64: https://www.dansschool.nl/ | K64: group lesson range
A65: K11_artist_fees | B65: GB | C65: 37 | F65: EUR per hour | G65: unknown | H65: 2026 | I65: private teachers | J65: https://www.superprof.co.uk/ | K65: GBP 31/h average, converted at ECB 0.83825
A66: K12_printing_wristbands | B66: SK | C66: 52 | F66: EUR per 1,000 pieces | G66: no | H66: 2026 | I66: Wristbands Europe | J66: https://www.wristbands-europe.com/ | K66: Tyvek 3/4 inch printed, 1,000-10,000 pcs
A67: K12_printing_wristbands | B67: SK | C67: 45 | F67: EUR per 1,000 pieces | G67: no | H67: 2026 | I67: Wristbands Europe | J67: https://www.wristbands-europe.com/ | K67: Tyvek plain
A68: K12_printing_wristbands | B68: SK | C68: 100 | F68: EUR per 1,000 pieces | G68: no | H68: 2026 | I68: Wristbands Europe | J68: https://www.wristbands-europe.com/ | K68: vinyl printed
A69: K13_photo_video | B69: ES | C69: 900 | F69: EUR per day | G69: no | H69: 2026 | I69: event photographer | J69: https://noomadik.com/ | K69: full day up to 8h, plus VAT
A70: K13_photo_video | B70: ES | C70: 450 | F70: EUR per day | G70: no | H70: 2026 | I70: event photographer | J70: https://noomadik.com/ | K70: half day
A71: K13_photo_video | B71: ES | C71: 650 | F71: EUR per day | G71: no | H71: 2026 | I71: event photographer | J71: https://noomadik.com/ | K71: half day
A72: K13_photo_video | B72: FR | C72: 1100 | F72: EUR per day | G72: no | H72: 2026 | I72: event photographer | J72: https://lesfilmsdegustave.com/ | K72: evening 4h
A73: K13_photo_video | B73: FR | C73: 1450 | F73: EUR per day | G73: no | H73: 2026 | I73: event photographer | J73: https://lesfilmsdegustave.com/ | K73: full day 8h
A74: K13_photo_video | B74: DE | C74: 880 | F74: EUR per day | G74: no | H74: 2026 | I74: event photographer | J74: https://offenblende.berlin/ | K74: full day 8h
A75: K13_photo_video | B75: DE | C75: 620 | F75: EUR per day | G75: no | H75: 2026 | I75: event photographer | J75: https://offenblende.berlin/ | K75: 4h
A76: K14_hotel_room_block | B76: DE | C76: 12 | F76: percent commission on net room revenue | G76: no | H76: 2026 | I76: Kempinski MICE terms | J76: https://www.kempinski.com/ | K76: 1 free room per 20 paid; 1 upgrade per 20
A78: K11 artist fees are private lesson rates, not congress fees: not used in the model. US hotel terms row removed.
